{"name": "test_get_max_dims_empty", "status": "passed", "description": "Test that get_max_dims raises an exception on empty DataTree", "start": 1757016773826, "stop": 1757016773826, "uuid": "04f111ac-ab10-4045-b9cb-d534e0e31de7", "historyId": "63b18134acd1bff31ef78bc7db9a9706", "testCaseId": "63b18134acd1bff31ef78bc7db9a9706", "fullName": "tests.unit.measurement_set.test_processing_set_xdt.TestProcessingSetXdtErrors#test_get_max_dims_empty", "labels": [{"name": "parentSuite", "value": "tests.unit.measurement_set"}, {"name": "suite", "value": "test_processing_set_xdt"}, {"name": "subSuite", "value": "TestProcessingSetXdtErrors"}, {"name": "host", "value": "pkrvm7jw40e0xgp"}, {"name": "thread", "value": "3826-MainThread"}, {"name": "framework", "value": "pytest"}, {"name": "language", "value": "cpython3"}, {"name": "package", "value": "tests.unit.measurement_set.test_processing_set_xdt"}], "titlePath": ["tests", "unit", "measurement_set", "test_processing_set_xdt.py", "TestProcessingSetXdtErrors"]}