{"name": "test_get_combined_field_and_source_xds_empty", "status": "passed", "description": "Test that get_combined_field_and_source_xds raises an exception on empty DataTree", "start": 1757016773831, "stop": 1757016773832, "uuid": "ca878d11-8e42-4b01-97bb-fa912116ddc8", "historyId": "0f02c2f82a4a5a025da710d09840ecbf", "testCaseId": "0f02c2f82a4a5a025da710d09840ecbf", "fullName": "tests.unit.measurement_set.test_processing_set_xdt.TestProcessingSetXdtErrors#test_get_combined_field_and_source_xds_empty", "labels": [{"name": "parentSuite", "value": "tests.unit.measurement_set"}, {"name": "suite", "value": "test_processing_set_xdt"}, {"name": "subSuite", "value": "TestProcessingSetXdtErrors"}, {"name": "host", "value": "pkrvm7jw40e0xgp"}, {"name": "thread", "value": "3826-MainThread"}, {"name": "framework", "value": "pytest"}, {"name": "language", "value": "cpython3"}, {"name": "package", "value": "tests.unit.measurement_set.test_processing_set_xdt"}], "titlePath": ["tests", "unit", "measurement_set", "test_processing_set_xdt.py", "TestProcessingSetXdtErrors"]}